Workbook

Sheet Overview
A1: SM Gold Sargodha — Keyword Research & SEO Analysis
A2: Prepared for: smgold.sargodha.pk | Niche: Gold jewellery / goldsmith | Market: Sargodha, Punjab, Pakistan
A4: How to use this workbook
A5: 1. Keyword Master List | B5: 108 keywords — 10 you provided + 98 expanded — each tagged with category, search intent, location level, language, estimated monthly volume tier, competition, priority and the exact page on your site it should target.
A6: 2. NLP & Intent Analysis | B6: Automatic breakdown (live formulas, recalculates if you edit the Master List) of search intent distribution, category mix, language mix, and priority mix — the semantic structure behind the keyword list.
A7: 3. Market Stats & Facts | B7: Real, sourced statistics on Pakistan's gold and jewellery market, local search behaviour, and Sargodha's population — context for why these keywords matter and roughly how big the opportunity is.
A8: 4. Content Recommendations | B8: Which keyword clusters your current 15 pages already cover, and where a dedicated new page (e.g. Bangles, Rings, Earrings) would let you rank for more of these terms.
A10: Methodology note
A11: Search volumes | B11: Pakistan lacks free public keyword-volume data (Google Keyword Planner requires an active ad spend account; Ahrefs/SEMrush require paid licences neither of which were available in this session). Volume Tier and Competition columns are therefore directional estimates built from: (a) real Pakistani gold-rate site traffic patterns found in research below, (b) general search-behaviour statistics for Pakistan, and (c) standard keyword-research heuristics (broad national terms > local/long-tail terms in volume; local/long-tail terms are far less competitive). Treat tiers as "relative to each other", not as guaranteed absolute monthly searches. For exact numbers, connect this keyword list to Google Search Console after launch, or run it through Google Keyword Planner / Ubersuggest once you have a few weeks of data.

Sheet Keyword Master List
A1: # | B1: Keyword | C1: Source | D1: Category | E1: Search Intent | F1: Location Level | G1: Language | H1: Est. Volume Tier | I1: Competition | J1: Priority | K1: Recommended Target Page
A2: 1 | B2: sm gold | C2: Seed | D2: Brand | E2: Navigational | F2: City - Sargodha | G2: English | H2: Medium | I2: Low | J2: 1 | K2: index.html (Home)
A3: 2 | B3: bangle | C3: Seed | D3: Product - Bangles | E3: Commercial Investigation | F3: Generic | G3: English | H3: High | I3: High | J3: 2 | K3: daily-wear-collection.html
A4: 3 | B4: bangles shop near me | C4: Seed | D4: Local | E4: Local | F4: Generic | G4: English | H4: Medium | I4: Low | J4: 1 | K4: contact.html
A5: 4 | B5: beautiful jewellery | C5: Seed | D5: Product - General | E5: Commercial Investigation | F5: Generic | G5: English | H5: High | I5: High | J5: 2 | K5: gallery.html
A6: 5 | B6: diamond ring | C6: Seed | D6: Product - Rings | E6: Commercial Investigation | F6: Generic | G6: English | H6: Very High | I6: Very High | J6: 3 | K6: New: Rings page
A7: 6 | B7: earrings | C7: Seed | D7: Product - Earrings | E7: Commercial Investigation | F7: Generic | G7: English | H7: Very High | I7: Very High | J7: 3 | K7: New: Earrings page
A8: 7 | B8: earrings design | C8: Seed | D8: Product - Earrings | E8: Commercial Investigation | F8: Generic | G8: English | H8: High | I8: Medium | J8: 1 | K8: New: Earrings page
A9: 8 | B9: earrings gold | C9: Seed | D9: Product - Earrings | E9: Commercial Investigation | F9: Generic | G9: English | H9: Medium | I9: Medium | J9: 1 | K9: daily-wear-collection.html
A10: 9 | B10: emerald bracelet | C10: Seed | D10: Product - Bracelets | E10: Commercial Investigation | F10: Generic | G10: English | H10: Low | I10: Low | J10: 2 | K10: New: Gemstone/Bracelets page
A11: 10 | B11: gold | C11: Seed | D11: Product - General | E11: Informational | F11: National | G11: English | H11: Very High | I11: Very High | J11: 3 | K11: gold-rate.html
A12: 11 | B12: sm gold sargodha | C12: Expanded | D12: Brand | E12: Navigational | F12: City - Sargodha | G12: English | H12: Low | I12: Low | J12: 1 | K12: index.html (Home)
A13: 12 | B13: sm gold shamsheer town | C13: Expanded | D13: Brand | E13: Navigational | F13: Hyperlocal | G13: English | H13: Low | I13: Low | J13: 2 | K13: contact.html
... A100: 99 | B100: difference between 18k and 21k gold | C100: Expanded | D100: Purity - Education | E100: Informational | F100: Generic | G100: English | H100: Medium | I100: Medium | J100: 2 | K100: gold-rate.html
A102: Priority 1 (highlighted) = best mix of realistic ranking chance + business relevance. Priority 2 = worth targeting once Priority 1 pages are strong. Priority 3 = very high competition national terms — long-term goal, not a launch priority.

Sheet NLP and Intent Analysis
A1: NLP & Search-Intent Analysis of the Keyword Master List
A2: All figures below are live formulas pulling from the "Keyword Master List" sheet — edit that sheet and these numbers update automatically.
A4: 1. Search intent distribution
A5: Intent | B5: Count | C5: % of total | D5: What it means
A6: Informational | B6: =COUNTIF('Keyword Master List'!$E$2:$E$100,A6) -> 19 | C6: =B6/SUM($B$6:$B$10) -> 0.19191919 | D6: People researching gold rates, purity, or general info — not ready to buy yet, but this is where trust and discoverability are built (and where 'gold rate today' traffic lives).
A7: Commercial Investigation | B7: =COUNTIF('Keyword Master List'!$E$2:$E$100,A7) -> 53 | C7: =B7/SUM($B$6:$B$10) -> 0.53535354 | D7: People comparing designs, styles and prices before choosing where to buy — your product/gallery pages should win these.
A8: Transactional | B8: =COUNTIF('Keyword Master List'!$E$2:$E$100,A8) -> 9 | C8: =B8/SUM($B$6:$B$10) -> 0.090909091 | D8: People ready to act now — repair, custom order, sell/exchange gold. Highest intent to contact you directly.
A9: Local | B9: =COUNTIF('Keyword Master List'!$E$2:$E$100,A9) -> 11 | C9: =B9/SUM($B$6:$B$10) -> 0.11111111 | D9: People searching with 'near me' or a place name — the single best-converting category (76% visit a business within 24 hours of a near-me search).
A10: Navigational | B10: =COUNTIF('Keyword Master List'!$E$2:$E$100,A10) -> 7 | C10: =B10/SUM($B$6:$B$10) -> 0.070707071 | D10: People already looking specifically for SM Gold by name — protect this with consistent NAP (Name/Address/Phone) and your Google Business Profile.
A12: 2. Semantic clusters (keyword categories)
A13: Category | B13: Count | C13: % of total | D13: Primary site page
A14: Brand | B14: =COUNTIF('Keyword Master List'!$D$2:$D$100,A14) -> 7 | C14: =B14/SUM($B$14:$B$26) -> 0.070707071 | D14: index.html / contact.html
A15: Local | B15: =COUNTIF('Keyword Master List'!$D$2:$D$100,A15) -> 14 | C15: =B15/SUM($B$14:$B$26) -> 0.14141414 | D15: contact.html / index.html
A16: Gold Rate | B16: =COUNTIF('Keyword Master List'!$D$2:$D$100,A16) -> 12 | C16: =B16/SUM($B$14:$B$26) -> 0.12121212 | D16: gold-rate.html
A17: Product - Bangles | B17: =COUNTIF('Keyword Master List'!$D$2:$D$100,A17) -> 8 | C17: =B17/SUM($B$14:$B$26) -> 0.080808081 | D17: daily-wear-collection.html (new Bangles page recommended)
A18: Product - Rings | B18: =COUNTIF('Keyword Master List'!$D$2:$D$100,A18) -> 8 | C18: =B18/SUM($B$14:$B$26) -> 0.080808081 | D18: custom-jewelry-making.html (new Rings page recommended)
A19: Product - Earrings | B19: =COUNTIF('Keyword Master List'!$D$2:$D$100,A19) -> 9 | C19: =B19/SUM($B$14:$B$26) -> 0.090909091 | D19: daily-wear-collection.html (new Earrings page recommended)
A20: Product - Bracelets | B20: =COUNTIF('Keyword Master List'!$D$2:$D$100,A20) -> 6 | C20: =B20/SUM($B$14:$B$26) -> 0.060606061 | D20: daily-wear-collection.html (new Gemstone page recommended)
A21: Product - General | B21: =COUNTIF('Keyword Master List'!$D$2:$D$100,A21) -> 7 | C21: =B21/SUM($B$14:$B$26) -> 0.070707071 | D21: gallery.html
A22: Product - Necklaces | B22: =COUNTIF('Keyword Master List'!$D$2:$D$100,A22) -> 6 | C22: =B22/SUM($B$14:$B$26) -> 0.060606061 | D22: daily-wear-collection.html (new Necklaces page recommended)
A23: Bridal - Wedding | B23: =COUNTIF('Keyword Master List'!$D$2:$D$100,A23) -> 8 | C23: =B23/SUM($B$14:$B$26) -> 0.080808081 | D23: bridal-gold-sets.html
A24: Service - Custom | B24: =COUNTIF('Keyword Master List'!$D$2:$D$100,A24) -> 3 | C24: =B24/SUM($B$14:$B$26) -> 0.03030303 | D24: custom-jewelry-making.html
A25: Service - Repair | B25: =COUNTIF('Keyword Master List'!$D$2:$D$100,A25) -> 5 | C25: =B25/SUM($B$14:$B$26) -> 0.050505051 | D25: gold-polishing-repair.html
A26: Purity - Education | B26: =COUNTIF('Keyword Master List'!$D$2:$D$100,A26) -> 6 | C26: =B26/SUM($B$14:$B$26) -> 0.060606061 | D26: gold-rate.html / faq.html
A28: 3. Language mix (English vs Roman Urdu)
A29: Language | B29: Count | C29: % of total | D29: Note
A30: English | B30: =COUNTIF('Keyword Master List'!$G$2:$G$100,A30) -> 88 | C30: =B30/SUM($B$30:$B$31) -> 0.88888889 | D30: Standard SEO-optimized copy — already your site's primary language.
A31: Roman Urdu | B31: =COUNTIF('Keyword Master List'!$G$2:$G$100,A31) -> 11 | C31: =B31/SUM($B$30:$B$31) -> 0.11111111 | D31: Terms like 'sona rate', 'sunar', 'jhumka', 'dulhan' — real local search behaviour. Weaving a few of these naturally into page copy/FAQs (without abandoning English) can capture searches competitors ignore.
A33: 4. Location specificity (entity extraction: place names)
A34: Location level | B34: Count | C34: % of total | D34: Note
A35: Hyperlocal | B35: =COUNTIF('Keyword Master List'!$F$2:$F$100,A35) -> 2 | C35: =B35/SUM($B$35:$B$39) -> 0.02020202 | D35: Shamsheer Town-level — near-zero competition, easiest wins.
A36: City - Sargodha | B36: =COUNTIF('Keyword Master List'!$F$2:$F$100,A36) -> 19 | C36: =B36/SUM($B$35:$B$39) -> 0.19191919 | D36: City-level — low competition, strong local buyer intent.
A37: Provincial - Punjab | B37: =COUNTIF('Keyword Master List'!$F$2:$F$100,A37) -> 1 | C37: =B37/SUM($B$35:$B$39) -> 0.01010101 | D37: Province-wide — much higher competition, longer-term target.
A38: National | B38: =COUNTIF('Keyword Master List'!$F$2:$F$100,A38) -> 29 | C38: =B38/SUM($B$35:$B$39) -> 0.29292929 | D38: Pakistan-wide — highest volume, highest competition (mostly the 'gold rate' terms).
A39: Generic | B39: =COUNTIF('Keyword Master List'!$F$2:$F$100,A39) -> 48 | C39: =B39/SUM($B$35:$B$39) -> 0.48484848 | D39: No place name in the query, but still winnable via on-page local signals (NAP, schema, reviews).
A41: 5. Launch priority mix
A42: Priority | B42: Count | C42: % of total | D42: Action
A43: 1 | B43: =COUNTIF('Keyword Master List'!$J$2:$J$100,A43) -> 44 | C43: =B43/SUM($B$43:$B$45) -> 0.44444444 | D43: Target first — write or strengthen page copy, headings and FAQs around these.
A44: 2 | B44: =COUNTIF('Keyword Master List'!$J$2:$J$100,A44) -> 41 | C44: =B44/SUM($B$43:$B$45) -> 0.41414141 | D44: Target next — natural extensions once Priority 1 pages are performing.
A45: 3 | B45: =COUNTIF('Keyword Master List'!$J$2:$J$100,A45) -> 14 | C45: =B45/SUM($B$43:$B$45) -> 0.14141414 | D45: Long-term / stretch — very high competition or too broad to rank for quickly; keep an eye on rather than chase.
...

Sheet Market Stats and Facts
A1: Market Stats & Facts — Context for the Keyword Strategy
A2: All figures below are from public sources found via live web search; each row cites where it came from.
A4: Stat | B4: Figure | C4: Relevance to SM Gold | D4: Source
A5: Sargodha district population (2023 census) | B5: 4,334,448 people (2,194,156 male / 2,139,911 female); 37.1% urban, 62.9% rural; growing ~2.70%/year | C5: This is your addressable local market size for 'near me' and city-name searches — a district of over 4.3 million people, still growing. | D5: Pakistan Bureau of Statistics, 2023 census (via pakinformation.com)
A6: Pakistan jewellery market revenue (2024) | B6: US $1.33 billion, projected to grow ~2.18%/year through 2028 | C6: Confirms steady, growing national demand for jewellery — the market SM Gold's gold-rate and product pages are competing in. | D6: Statista Market Forecast — Jewelry Pakistan
A7: Pakistan jewellery gold demand | B7: 17.5 tonnes in 2024, 15.8 tonnes in 2025 (-10% YoY) as gold prices rose | C7: Rising gold prices are pushing some buyers toward smaller/lighter pieces and daily-wear designs rather than heavy sets — supports promoting your Daily Wear Collection and transparent daily rate updates. | D7: World Gold Council, Gold Demand Trends
A8: Pakistan gold bar & coin demand | B8: 19.0 tonnes in 2024, 19.4 tonnes in 2025 (+2% YoY) | C8: Investment-driven gold buying is holding steady even as jewellery demand softens — an opening to mention bullion/coin availability if you offer it. | D8: World Gold Council, Gold Demand Trends
A9: Gold price trend | B9: Gold hit a record run of new highs in 2025-2026 (Pakistan 24K around Rs 424,000-428,000/tola in July 2026) | C9: Explains why 'gold rate today' is such a heavily and repeatedly searched query — a daily-updated rate page is a genuine competitive advantage, not just a nice-to-have. | D9: UrduPoint / Business Recorder / PolicyBazaar gold rate pages
A10: Wedding season jewellery spend shift | B10: Rising prices are pushing some families toward gold-plated/imitation bridal sets (Rs 40,000-60,000) instead of solid gold (which can run into the hundreds of thousands) | C10: Real gold, fair pricing and a purity guarantee is a stronger trust pitch than ever while competitors' imitation-jewellery messaging grows — lean into '100% Pure Gold Guaranteed' across bridal content. | D10: Al Jazeera; Shehnai.pk wedding cost guide
A11: Local wedding market size (regional) | B11: One Karachi wedding season alone was estimated at Rs 33 billion | C11: Illustrates how large occasion-driven jewellery spending is nationally — Sargodha's own wedding season is a meaningful, recurring local revenue driver worth seasonal campaigns around. | D11: Dawn News, 'Wedding economy' report
A12: Pakistan internet users (2025) | B12: 117 million people online, 45.6% penetration | C12: Just under half the country is online — still room to grow but already a large enough base that a well-optimized website is worth the investment. | D12: DataReportal, Digital 2026: Pakistan
A13: Pakistan social media users (2025) | B13: 79.9 million (31.2% of population); Facebook 67.5M, Messenger 54.2M, Instagram 23.5M | C13: Facebook/Messenger and Instagram remain the biggest channels to pair with your website and WhatsApp — worth cross-linking your site's WhatsApp CTA to these platforms. | D13: DataReportal / NapoleonCat, 2025
A14: 'Near me' search growth | B14: 900% growth over two years; ~800 million 'near me' searches/month (US data, directionally global) | C14: Confirms 'near me' and hyperlocal terms (bangles shop near me, goldsmith near me, gold shop near me) are a fast-growing, high-value category worth prioritizing. | D14: Google/industry local-search research (via BizIQ, HubSpot)
A15: Local search intent share | B15: 46% of all Google searches now have local intent (up from 30% in 2019) | C15: Nearly half of all searches are local — reinforces investing in city/hyperlocal keyword variants, not just national 'gold jewellery' terms. | D15: Local SEO research (Hennessey Digital, BizIQ)
... A17: Local search-to-visit conversion | B17: 76% of near-me mobile searchers visit a business within 24 hours; 78% of local mobile searches lead to an offline purchase | C17: The single strongest argument for prioritizing hyperlocal keywords over broad national ones — they convert into real shop visits fastest. | D17: Local SEO research aggregation, 2026

Sheet Content Recommendations
A1: Content Recommendations — Coverage vs. Gaps
A2: How the 99 keywords map onto your current 15 pages, and where a new page would unlock more of them.
A4: A. Well covered by your current pages
A5: Page | B5: Keyword clusters it already targets | C5: Status
A6: gold-rate.html | B6: Gold Rate cluster (24K/22K/21K/18K, 'today', Sargodha rate, Roman Urdu 'sona rate'), Purity/Education cluster | C6: Strong — already the dedicated page these ~18 keywords need
A7: bridal-gold-sets.html | B7: Bridal - Wedding cluster (bridal set, dulhan, walima, Pakistani bridal set, 7-piece set) | C7: Strong — matches this cluster well
A8: custom-jewelry-making.html | B8: Service - Custom cluster, part of Product - Rings cluster (engagement/mens rings) | C8: Good — could add ring-specific copy
A9: gold-polishing-repair.html | B9: Service - Repair cluster (repair, polishing, exchange, cleaning) | C9: Strong — matches this cluster well
A10: daily-wear-collection.html | B10: Product - General/Bangles/Earrings/Necklaces long-tail terms, currently grouped together | C10: Partial — covers the terms but not each as its own ranking target
A11: about.html / contact.html | B11: Local cluster (near me, goldsmith, trusted, jewellers near me Sargodha), Brand cluster | C11: Strong — good NAP consistency, keep it that way
A12: gallery.html | B12: Product - General ('beautiful jewellery design', 'gold jewellery design') | C12: Good — add descriptive alt text/captions using these exact phrases
A14: B. Gaps — keywords with no dedicated page yet
A15: Suggested new page | B15: Keywords it would target | C15: Why it's worth it
A16: Bangles (gold-bangles.html) | B16: gold bangles design, gold bangles set, bangles design 2026, kara/churi bangles, bridal bangles set, 22k gold bangles, bangles shop near me | C16: "bangle" and "bangles shop near me" were two of your original 10 seed keywords — this is the single highest-value gap.
A17: Earrings (gold-earrings.html) | B17: earrings, earrings design, earrings gold, gold earrings design, jhumka earrings, stud earrings, wedding earrings | C17: Three of your seed keywords are earrings-related — currently these all point at one shared section of Daily Wear Collection instead of their own page.
A18: Rings (gold-rings.html) | B18: diamond ring, diamond ring price Pakistan, gold ring design for female, mens gold ring, engagement ring Pakistan | C18: "Diamond ring" was a seed keyword and is high-volume — currently only loosely covered by Custom Jewelry Making.
A19: Gemstone / Bracelets (gemstone-jewellery.html) | B19: emerald bracelet, emerald bracelet price, emerald jewellery Pakistan, gold bracelet design, panna stone jewellery | C19: "Emerald bracelet" was a seed keyword with no real home on the current site — low competition, easy first-page opportunity.
A20: Necklaces (gold-necklaces.html) | B20: gold necklace design, gold set design, gold pendant design, gold chain design, name pendant | C20: Necklaces are currently folded into Daily Wear Collection; a dedicated page would let it rank for its own design-related searches.
A22: C. Quick-win action list (highest impact, lowest effort first)
A23: 1. Add the exact Priority-1 keywords from the Master List into existing page titles, H1/H2s and first paragraphs where they fit naturally (never force a keyword into a sentence that reads awkwardly).
A24: 2. Create the Bangles and Earrings pages first — both had multiple seed keywords and currently share one generic section.
A25: 3. Add 3-4 FAQ entries using the exact phrasing of the Purity - Education keywords (e.g. "Is 21K or 22K gold better?") — low competition, easy to rank, and builds trust/E-E-A-T.
A26: 4. Set up (or verify) a Google Business Profile for SM Gold with the exact address and phone used on the site — this is what actually wins 'near me' and map-pack results, more than on-page text alone.
A27: 5. Weave 2-3 Roman Urdu terms (sona rate, sunar, jhumka) naturally into relevant page copy — real local search behaviour competitors are likely ignoring.
A28: 6. Once live, connect Google Search Console and revisit this workbook after 4-6 weeks — real impression/click data will confirm or correct the Volume Tier and Priority estimates.
